Workbook

Sheet P01
A1: P01 (Anna, 68 anni · Profilo A)
A3: SEZIONE A — Informazioni generali
A4: A1 | B4: Quanti anni hai? | C4: Meno di 25 | D4: 25–40 | E4: 41–60 | F4: Oltre 60
A5: A2 | B5: Con quale frequenza usi uno smartphone? | C5: Ogni giorno | D5: Qualche volta a settimana | E5: Raramente | F5: Mai
A6: A3 | B6: Con quale frequenza usi un computer o tablet? | C6: Ogni giorno | D6: Qualche volta a settimana | E6: Raramente | F6: Mai
A7: A4 | B7: Hai mai usato app o siti per conservare foto o ricordi di famiglia? | C7: Sì | D7: No
A9: SEZIONE B — Facilità d'uso (ISE)
A10: Item | B10: Affermazione | C10: Per niente d'accordo | D10: Poco d'accordo | E10: Abbastanza d'accordo | F10: Molto d'accordo | G10: Completamente d'accordo | H10: Valore
A11: B1 | B11: Ho trovato il sistema facile da usare fin da subito | F11: X | H11: =IF(C11="X",1)+IF(D11="X",2)+IF(E11="X",3)+IF(F11="X",4)+IF(G11="X",5) -> 4
A12: B2 | B12: Ho capito subito cosa fare in ogni schermata | F12: X | H12: =IF(C12="X",1)+IF(D12="X",2)+IF(E12="X",3)+IF(F12="X",4)+IF(G12="X",5) -> 4
A13: B3 | B13: Non ho avuto bisogno di aiuto per completare i compiti | E13: X | H13: =IF(C13="X",1)+IF(D13="X",2)+IF(E13="X",3)+IF(F13="X",4)+IF(G13="X",5) -> 3
A14: B4 | B14: Le etichette e i pulsanti erano chiari e comprensibili | G14: X | H14: =IF(C14="X",1)+IF(D14="X",2)+IF(E14="X",3)+IF(F14="X",4)+IF(G14="X",5) -> 5
A15: B5 | B15: Il sistema mi ha sempre fatto capire cosa stava succedendo | G15: X | H15: =IF(C15="X",1)+IF(D15="X",2)+IF(E15="X",3)+IF(F15="X",4)+IF(G15="X",5) -> 5
B16: MEDIA Facilità d'uso | H16: =AVERAGE(H11:H15) -> 4.2
A18: SEZIONE C — Competenza percepita (IKS)
A19: Item | B19: Affermazione | C19: Per niente d'accordo | D19: Poco d'accordo | E19: Abbastanza d'accordo | F19: Molto d'accordo | G19: Completamente d'accordo | H19: Valore
A20: C1 | B20: Mi sono sentito/a capace di usare il sistema in autonomia | F20: X | H20: =IF(C20="X",1)+IF(D20="X",2)+IF(E20="X",3)+IF(F20="X",4)+IF(G20="X",5) -> 4
A21: C2 | B21: Sapevo sempre quale sarebbe stato l'effetto delle mie azioni | F21: X | H21: =IF(C21="X",1)+IF(D21="X",2)+IF(E21="X",3)+IF(F21="X",4)+IF(G21="X",5) -> 4
A22: C3 | B22: Non ho avuto paura di fare errori irreversibili | G22: X | H22: =IF(C22="X",1)+IF(D22="X",2)+IF(E22="X",3)+IF(F22="X",4)+IF(G22="X",5) -> 5
A23: C4 | B23: Con un po' di pratica userei questo sistema senza difficoltà | G23: X | H23: =IF(C23="X",1)+IF(D23="X",2)+IF(E23="X",3)+IF(F23="X",4)+IF(G23="X",5) -> 5
B24: MEDIA Competenza percepita | H24: =AVERAGE(H20:H23) -> 4.5
A26: SEZIONE D — Senso di controllo (IPC)
A27: Item | B27: Affermazione | C27: Per niente d'accordo | D27: Poco d'accordo | E27: Abbastanza d'accordo | F27: Molto d'accordo | G27: Completamente d'accordo | H27: Valore
A28: D1 | B28: Ho sempre saputo dove mi trovavo all'interno del sistema | F28: X | H28: =IF(C28="X",1)+IF(D28="X",2)+IF(E28="X",3)+IF(F28="X",4)+IF(G28="X",5) -> 4
A29: D2 | B29: Ho potuto tornare indietro o correggere facilmente gli errori | G29: X | H29: =IF(C29="X",1)+IF(D29="X",2)+IF(E29="X",3)+IF(F29="X",4)+IF(G29="X",5) -> 5
A30: D3 | B30: Il sistema ha risposto in modo coerente con quello che mi aspettavo | F30: X | H30: =IF(C30="X",1)+IF(D30="X",2)+IF(E30="X",3)+IF(F30="X",4)+IF(G30="X",5) -> 4
A31: D4 | B31: Mi sono sentito/a in controllo dell'interazione in ogni momento | F31: X | H31: =IF(C31="X",1)+IF(D31="X",2)+IF(E31="X",3)+IF(F31="X",4)+IF(G31="X",5) -> 4
B32: MEDIA Senso di controllo | H32: =AVERAGE(H28:H31) -> 4.25
A34: SEZIONE E — Motivazione e coinvolgimento (IMOT)
A35: Item | B35: Affermazione | C35: Per niente d'accordo | D35: Poco d'accordo | E35: Abbastanza d'accordo | F35: Molto d'accordo | G35: Completamente d'accordo | H35: Valore
A36: E1 | B36: Ho trovato il sistema interessante e coinvolgente | G36: X | H36: =IF(C36="X",1)+IF(D36="X",2)+IF(E36="X",3)+IF(F36="X",4)+IF(G36="X",5) -> 5
A37: E2 | B37: Userei questo sistema per raccogliere i ricordi della mia famiglia | G37: X | H37: =IF(C37="X",1)+IF(D37="X",2)+IF(E37="X",3)+IF(F37="X",4)+IF(G37="X",5) -> 5
A38: E3 | B38: L'esperienza mi ha fatto venire voglia di esplorare di più | G38: X | H38: =IF(C38="X",1)+IF(D38="X",2)+IF(E38="X",3)+IF(F38="X",4)+IF(G38="X",5) -> 5
A39: E4 | B39: Il sistema mi ha fatto sentire che stavo facendo qualcosa di significativo | G39: X | H39: =IF(C39="X",1)+IF(D39="X",2)+IF(E39="X",3)+IF(F39="X",4)+IF(G39="X",5) -> 5
B40: MEDIA Motivazione e coinvolgimento | H40: =AVERAGE(H36:H39) -> 5
A42: SEZIONE F — Domande sui task
A43: F1a | B43: T1 · Come hai trovato la conversazione guidata con Iris? | C43: Abbastanza naturale
A44: F1b | B44: T1 · C'è qualcosa che Iris avrebbe dovuto chiederti e non ti ha chiesto? | C44: Non credo
A45: F2a | B45: T3 · Aggiungere un familiare all'albero è stato: | C45: Abbastanza semplice
A46: F2b | B46: T3 · Hai capito subito come collegare il nuovo membro alle persone già presenti? | C46: Dopo un po'
...

Sheet P02
A1: P02 (Giuseppe, 72 anni · Profilo A)
A3: SEZIONE A — Informazioni generali
A4: A1 | B4: Quanti anni hai? | C4: Meno di 25 | D4: 25–40 | E4: 41–60 | F4: Oltre 60
A5: A2 | B5: Con quale frequenza usi uno smartphone? | C5: Ogni giorno | D5: Qualche volta a settimana | E5: Raramente | F5: Mai
A6: A3 | B6: Con quale frequenza usi un computer o tablet? | C6: Ogni giorno | D6: Qualche volta a settimana | E6: Raramente | F6: Mai
A7: A4 | B7: Hai mai usato app o siti per conservare foto o ricordi di famiglia? | C7: Sì | D7: No
A9: SEZIONE B — Facilità d'uso (ISE)
A10: Item | B10: Affermazione | C10: Per niente d'accordo | D10: Poco d'accordo | E10: Abbastanza d'accordo | F10: Molto d'accordo | G10: Completamente d'accordo | H10: Valore
A11: B1 | B11: Ho trovato il sistema facile da usare fin da subito | E11: X | H11: =IF(C11="X",1)+IF(D11="X",2)+IF(E11="X",3)+IF(F11="X",4)+IF(G11="X",5) -> 3
A12: B2 | B12: Ho capito subito cosa fare in ogni schermata | F12: X | H12: =IF(C12="X",1)+IF(D12="X",2)+IF(E12="X",3)+IF(F12="X",4)+IF(G12="X",5) -> 4
A13: B3 | B13: Non ho avuto bisogno di aiuto per completare i compiti | E13: X | H13: =IF(C13="X",1)+IF(D13="X",2)+IF(E13="X",3)+IF(F13="X",4)+IF(G13="X",5) -> 3
A14: B4 | B14: Le etichette e i pulsanti erano chiari e comprensibili | F14: X | H14: =IF(C14="X",1)+IF(D14="X",2)+IF(E14="X",3)+IF(F14="X",4)+IF(G14="X",5) -> 4
A15: B5 | B15: Il sistema mi ha sempre fatto capire cosa stava succedendo | F15: X | H15: =IF(C15="X",1)+IF(D15="X",2)+IF(E15="X",3)+IF(F15="X",4)+IF(G15="X",5) -> 4
B16: MEDIA Facilità d'uso | H16: =AVERAGE(H11:H15) -> 3.6
A18: SEZIONE C — Competenza percepita (IKS)
A19: Item | B19: Affermazione | C19: Per niente d'accordo | D19: Poco d'accordo | E19: Abbastanza d'accordo | F19: Molto d'accordo | G19: Completamente d'accordo | H19: Valore
A20: C1 | B20: Mi sono sentito/a capace di usare il sistema in autonomia | F20: X | H20: =IF(C20="X",1)+IF(D20="X",2)+IF(E20="X",3)+IF(F20="X",4)+IF(G20="X",5) -> 4
A21: C2 | B21: Sapevo sempre quale sarebbe stato l'effetto delle mie azioni | F21: X | H21: =IF(C21="X",1)+IF(D21="X",2)+IF(E21="X",3)+IF(F21="X",4)+IF(G21="X",5) -> 4
A22: C3 | B22: Non ho avuto paura di fare errori irreversibili | F22: X | H22: =IF(C22="X",1)+IF(D22="X",2)+IF(E22="X",3)+IF(F22="X",4)+IF(G22="X",5) -> 4
A23: C4 | B23: Con un po' di pratica userei questo sistema senza difficoltà | G23: X | H23: =IF(C23="X",1)+IF(D23="X",2)+IF(E23="X",3)+IF(F23="X",4)+IF(G23="X",5) -> 5
B24: MEDIA Competenza percepita | H24: =AVERAGE(H20:H23) -> 4.25
A26: SEZIONE D — Senso di controllo (IPC)
A27: Item | B27: Affermazione | C27: Per niente d'accordo | D27: Poco d'accordo | E27: Abbastanza d'accordo | F27: Molto d'accordo | G27: Completamente d'accordo | H27: Valore
A28: D1 | B28: Ho sempre saputo dove mi trovavo all'interno del sistema | E28: X | H28: =IF(C28="X",1)+IF(D28="X",2)+IF(E28="X",3)+IF(F28="X",4)+IF(G28="X",5) -> 3
A29: D2 | B29: Ho potuto tornare indietro o correggere facilmente gli errori | F29: X | H29: =IF(C29="X",1)+IF(D29="X",2)+IF(E29="X",3)+IF(F29="X",4)+IF(G29="X",5) -> 4
A30: D3 | B30: Il sistema ha risposto in modo coerente con quello che mi aspettavo | F30: X | H30: =IF(C30="X",1)+IF(D30="X",2)+IF(E30="X",3)+IF(F30="X",4)+IF(G30="X",5) -> 4
A31: D4 | B31: Mi sono sentito/a in controllo dell'interazione in ogni momento | F31: X | H31: =IF(C31="X",1)+IF(D31="X",2)+IF(E31="X",3)+IF(F31="X",4)+IF(G31="X",5) -> 4
B32: MEDIA Senso di controllo | H32: =AVERAGE(H28:H31) -> 3.75
A34: SEZIONE E — Motivazione e coinvolgimento (IMOT)
A35: Item | B35: Affermazione | C35: Per niente d'accordo | D35: Poco d'accordo | E35: Abbastanza d'accordo | F35: Molto d'accordo | G35: Completamente d'accordo | H35: Valore
A36: E1 | B36: Ho trovato il sistema interessante e coinvolgente | G36: X | H36: =IF(C36="X",1)+IF(D36="X",2)+IF(E36="X",3)+IF(F36="X",4)+IF(G36="X",5) -> 5
A37: E2 | B37: Userei questo sistema per raccogliere i ricordi della mia famiglia | G37: X | H37: =IF(C37="X",1)+IF(D37="X",2)+IF(E37="X",3)+IF(F37="X",4)+IF(G37="X",5) -> 5
A38: E3 | B38: L'esperienza mi ha fatto venire voglia di esplorare di più | F38: X | H38: =IF(C38="X",1)+IF(D38="X",2)+IF(E38="X",3)+IF(F38="X",4)+IF(G38="X",5) -> 4
A39: E4 | B39: Il sistema mi ha fatto sentire che stavo facendo qualcosa di significativo | G39: X | H39: =IF(C39="X",1)+IF(D39="X",2)+IF(E39="X",3)+IF(F39="X",4)+IF(G39="X",5) -> 5
B40: MEDIA Motivazione e coinvolgimento | H40: =AVERAGE(H36:H39) -> 4.75
A42: SEZIONE F — Domande sui task
A43: F1a | B43: T1 · Come hai trovato la conversazione guidata con Iris? | C43: Simpatica
A44: F1b | B44: T1 · C'è qualcosa che Iris avrebbe dovuto chiederti e non ti ha chiesto? | C44: Il nome del mio paese natale non è stato registrato la prima volta.
A45: F2a | B45: T3 · Aggiungere un familiare all'albero è stato: | C45: Un po' difficile
A46: F2b | B46: T3 · Hai capito subito come collegare il nuovo membro alle persone già presenti? | C46: Dopo un po'
...

Sheet P03
A1: P03 (Rosanna, 65 anni · Profilo A)
A3: SEZIONE A — Informazioni generali
A4: A1 | B4: Quanti anni hai? | C4: Meno di 25 | D4: 25–40 | E4: 41–60 | F4: Oltre 60
A5: A2 | B5: Con quale frequenza usi uno smartphone? | C5: Ogni giorno | D5: Qualche volta a settimana | E5: Raramente | F5: Mai
A6: A3 | B6: Con quale frequenza usi un computer o tablet? | C6: Ogni giorno | D6: Qualche volta a settimana | E6: Raramente | F6: Mai
A7: A4 | B7: Hai mai usato app o siti per conservare foto o ricordi di famiglia? | C7: Sì | D7: No
B8: Se sì, quali: Google Foto (poco)
A10: SEZIONE B — Facilità d'uso (ISE)
A11: Item | B11: Affermazione | C11: Per niente d'accordo | D11: Poco d'accordo | E11: Abbastanza d'accordo | F11: Molto d'accordo | G11: Completamente d'accordo | H11: Valore
A12: B1 | B12: Ho trovato il sistema facile da usare fin da subito | F12: X | H12: =IF(C12="X",1)+IF(D12="X",2)+IF(E12="X",3)+IF(F12="X",4)+IF(G12="X",5) -> 4
A13: B2 | B13: Ho capito subito cosa fare in ogni schermata | F13: X | H13: =IF(C13="X",1)+IF(D13="X",2)+IF(E13="X",3)+IF(F13="X",4)+IF(G13="X",5) -> 4
A14: B3 | B14: Non ho avuto bisogno di aiuto per completare i compiti | F14: X | H14: =IF(C14="X",1)+IF(D14="X",2)+IF(E14="X",3)+IF(F14="X",4)+IF(G14="X",5) -> 4
A15: B4 | B15: Le etichette e i pulsanti erano chiari e comprensibili | G15: X | H15: =IF(C15="X",1)+IF(D15="X",2)+IF(E15="X",3)+IF(F15="X",4)+IF(G15="X",5) -> 5
A16: B5 | B16: Il sistema mi ha sempre fatto capire cosa stava succedendo | G16: X | H16: =IF(C16="X",1)+IF(D16="X",2)+IF(E16="X",3)+IF(F16="X",4)+IF(G16="X",5) -> 5
B17: MEDIA Facilità d'uso | H17: =AVERAGE(H12:H16) -> 4.4
A19: SEZIONE C — Competenza percepita (IKS)
A20: Item | B20: Affermazione | C20: Per niente d'accordo | D20: Poco d'accordo | E20: Abbastanza d'accordo | F20: Molto d'accordo | G20: Completamente d'accordo | H20: Valore
A21: C1 | B21: Mi sono sentito/a capace di usare il sistema in autonomia | G21: X | H21: =IF(C21="X",1)+IF(D21="X",2)+IF(E21="X",3)+IF(F21="X",4)+IF(G21="X",5) -> 5
A22: C2 | B22: Sapevo sempre quale sarebbe stato l'effetto delle mie azioni | F22: X | H22: =IF(C22="X",1)+IF(D22="X",2)+IF(E22="X",3)+IF(F22="X",4)+IF(G22="X",5) -> 4
A23: C3 | B23: Non ho avuto paura di fare errori irreversibili | E23: X | H23: =IF(C23="X",1)+IF(D23="X",2)+IF(E23="X",3)+IF(F23="X",4)+IF(G23="X",5) -> 3
A24: C4 | B24: Con un po' di pratica userei questo sistema senza difficoltà | G24: X | H24: =IF(C24="X",1)+IF(D24="X",2)+IF(E24="X",3)+IF(F24="X",4)+IF(G24="X",5) -> 5
B25: MEDIA Competenza percepita | H25: =AVERAGE(H21:H24) -> 4.25
A27: SEZIONE D — Senso di controllo (IPC)
A28: Item | B28: Affermazione | C28: Per niente d'accordo | D28: Poco d'accordo | E28: Abbastanza d'accordo | F28: Molto d'accordo | G28: Completamente d'accordo | H28: Valore
A29: D1 | B29: Ho sempre saputo dove mi trovavo all'interno del sistema | F29: X | H29: =IF(C29="X",1)+IF(D29="X",2)+IF(E29="X",3)+IF(F29="X",4)+IF(G29="X",5) -> 4
A30: D2 | B30: Ho potuto tornare indietro o correggere facilmente gli errori | E30: X | H30: =IF(C30="X",1)+IF(D30="X",2)+IF(E30="X",3)+IF(F30="X",4)+IF(G30="X",5) -> 3
A31: D3 | B31: Il sistema ha risposto in modo coerente con quello che mi aspettavo | F31: X | H31: =IF(C31="X",1)+IF(D31="X",2)+IF(E31="X",3)+IF(F31="X",4)+IF(G31="X",5) -> 4
A32: D4 | B32: Mi sono sentito/a in controllo dell'interazione in ogni momento | F32: X | H32: =IF(C32="X",1)+IF(D32="X",2)+IF(E32="X",3)+IF(F32="X",4)+IF(G32="X",5) -> 4
B33: MEDIA Senso di controllo | H33: =AVERAGE(H29:H32) -> 3.75
A35: SEZIONE E — Motivazione e coinvolgimento (IMOT)
A36: Item | B36: Affermazione | C36: Per niente d'accordo | D36: Poco d'accordo | E36: Abbastanza d'accordo | F36: Molto d'accordo | G36: Completamente d'accordo | H36: Valore
A37: E1 | B37: Ho trovato il sistema interessante e coinvolgente | G37: X | H37: =IF(C37="X",1)+IF(D37="X",2)+IF(E37="X",3)+IF(F37="X",4)+IF(G37="X",5) -> 5
A38: E2 | B38: Userei questo sistema per raccogliere i ricordi della mia famiglia | F38: X | H38: =IF(C38="X",1)+IF(D38="X",2)+IF(E38="X",3)+IF(F38="X",4)+IF(G38="X",5) -> 4
A39: E3 | B39: L'esperienza mi ha fatto venire voglia di esplorare di più | G39: X | H39: =IF(C39="X",1)+IF(D39="X",2)+IF(E39="X",3)+IF(F39="X",4)+IF(G39="X",5) -> 5
A40: E4 | B40: Il sistema mi ha fatto sentire che stavo facendo qualcosa di significativo | G40: X | H40: =IF(C40="X",1)+IF(D40="X",2)+IF(E40="X",3)+IF(F40="X",4)+IF(G40="X",5) -> 5
B41: MEDIA Motivazione e coinvolgimento | H41: =AVERAGE(H37:H40) -> 4.75
A43: SEZIONE F — Domande sui task
A44: F1a | B44: T1 · Come hai trovato la conversazione guidata con Iris? | C44: Molto naturale
A45: F1b | B45: T1 · C'è qualcosa che Iris avrebbe dovuto chiederti e non ti ha chiesto? | C45: No
A46: F2a | B46: T3 · Aggiungere un familiare all'albero è stato: | C46: Abbastanza semplice
...

Sheet P04
A1: P04 (Marco B., 45 anni · Profilo B)
A3: SEZIONE A — Informazioni generali
A4: A1 | B4: Quanti anni hai? | C4: Meno di 25 | D4: 25–40 | E4: 41–60 | F4: Oltre 60
A5: A2 | B5: Con quale frequenza usi uno smartphone? | C5: Ogni giorno | D5: Qualche volta a settimana | E5: Raramente | F5: Mai
A6: A3 | B6: Con quale frequenza usi un computer o tablet? | C6: Ogni giorno | D6: Qualche volta a settimana | E6: Raramente | F6: Mai
A7: A4 | B7: Hai mai usato app o siti per conservare foto o ricordi di famiglia? | C7: Sì | D7: No
B8: Se sì, quali: Google Foto, iCloud
A10: SEZIONE B — Facilità d'uso (ISE)
A11: Item | B11: Affermazione | C11: Per niente d'accordo | D11: Poco d'accordo | E11: Abbastanza d'accordo | F11: Molto d'accordo | G11: Completamente d'accordo | H11: Valore
A12: B1 | B12: Ho trovato il sistema facile da usare fin da subito | G12: X | H12: =IF(C12="X",1)+IF(D12="X",2)+IF(E12="X",3)+IF(F12="X",4)+IF(G12="X",5) -> 5
A13: B2 | B13: Ho capito subito cosa fare in ogni schermata | G13: X | H13: =IF(C13="X",1)+IF(D13="X",2)+IF(E13="X",3)+IF(F13="X",4)+IF(G13="X",5) -> 5
A14: B3 | B14: Non ho avuto bisogno di aiuto per completare i compiti | G14: X | H14: =IF(C14="X",1)+IF(D14="X",2)+IF(E14="X",3)+IF(F14="X",4)+IF(G14="X",5) -> 5
A15: B4 | B15: Le etichette e i pulsanti erano chiari e comprensibili | G15: X | H15: =IF(C15="X",1)+IF(D15="X",2)+IF(E15="X",3)+IF(F15="X",4)+IF(G15="X",5) -> 5
A16: B5 | B16: Il sistema mi ha sempre fatto capire cosa stava succedendo | G16: X | H16: =IF(C16="X",1)+IF(D16="X",2)+IF(E16="X",3)+IF(F16="X",4)+IF(G16="X",5) -> 5
B17: MEDIA Facilità d'uso | H17: =AVERAGE(H12:H16) -> 5
A19: SEZIONE C — Competenza percepita (IKS)
A20: Item | B20: Affermazione | C20: Per niente d'accordo | D20: Poco d'accordo | E20: Abbastanza d'accordo | F20: Molto d'accordo | G20: Completamente d'accordo | H20: Valore
A21: C1 | B21: Mi sono sentito/a capace di usare il sistema in autonomia | G21: X | H21: =IF(C21="X",1)+IF(D21="X",2)+IF(E21="X",3)+IF(F21="X",4)+IF(G21="X",5) -> 5
A22: C2 | B22: Sapevo sempre quale sarebbe stato l'effetto delle mie azioni | G22: X | H22: =IF(C22="X",1)+IF(D22="X",2)+IF(E22="X",3)+IF(F22="X",4)+IF(G22="X",5) -> 5
A23: C3 | B23: Non ho avuto paura di fare errori irreversibili | E23: X | H23: =IF(C23="X",1)+IF(D23="X",2)+IF(E23="X",3)+IF(F23="X",4)+IF(G23="X",5) -> 3
A24: C4 | B24: Con un po' di pratica userei questo sistema senza difficoltà | G24: X | H24: =IF(C24="X",1)+IF(D24="X",2)+IF(E24="X",3)+IF(F24="X",4)+IF(G24="X",5) -> 5
B25: MEDIA Competenza percepita | H25: =AVERAGE(H21:H24) -> 4.5
A27: SEZIONE D — Senso di controllo (IPC)
A28: Item | B28: Affermazione | C28: Per niente d'accordo | D28: Poco d'accordo | E28: Abbastanza d'accordo | F28: Molto d'accordo | G28: Completamente d'accordo | H28: Valore
A29: D1 | B29: Ho sempre saputo dove mi trovavo all'interno del sistema | G29: X | H29: =IF(C29="X",1)+IF(D29="X",2)+IF(E29="X",3)+IF(F29="X",4)+IF(G29="X",5) -> 5
A30: D2 | B30: Ho potuto tornare indietro o correggere facilmente gli errori | G30: X | H30: =IF(C30="X",1)+IF(D30="X",2)+IF(E30="X",3)+IF(F30="X",4)+IF(G30="X",5) -> 5
A31: D3 | B31: Il sistema ha risposto in modo coerente con quello che mi aspettavo | F31: X | H31: =IF(C31="X",1)+IF(D31="X",2)+IF(E31="X",3)+IF(F31="X",4)+IF(G31="X",5) -> 4
A32: D4 | B32: Mi sono sentito/a in controllo dell'interazione in ogni momento | G32: X | H32: =IF(C32="X",1)+IF(D32="X",2)+IF(E32="X",3)+IF(F32="X",4)+IF(G32="X",5) -> 5
B33: MEDIA Senso di controllo | H33: =AVERAGE(H29:H32) -> 4.75
A35: SEZIONE E — Motivazione e coinvolgimento (IMOT)
A36: Item | B36: Affermazione | C36: Per niente d'accordo | D36: Poco d'accordo | E36: Abbastanza d'accordo | F36: Molto d'accordo | G36: Completamente d'accordo | H36: Valore
A37: E1 | B37: Ho trovato il sistema interessante e coinvolgente | F37: X | H37: =IF(C37="X",1)+IF(D37="X",2)+IF(E37="X",3)+IF(F37="X",4)+IF(G37="X",5) -> 4
A38: E2 | B38: Userei questo sistema per raccogliere i ricordi della mia famiglia | E38: X | H38: =IF(C38="X",1)+IF(D38="X",2)+IF(E38="X",3)+IF(F38="X",4)+IF(G38="X",5) -> 3
A39: E3 | B39: L'esperienza mi ha fatto venire voglia di esplorare di più | F39: X | H39: =IF(C39="X",1)+IF(D39="X",2)+IF(E39="X",3)+IF(F39="X",4)+IF(G39="X",5) -> 4
A40: E4 | B40: Il sistema mi ha fatto sentire che stavo facendo qualcosa di significativo | G40: X | H40: =IF(C40="X",1)+IF(D40="X",2)+IF(E40="X",3)+IF(F40="X",4)+IF(G40="X",5) -> 5
B41: MEDIA Motivazione e coinvolgimento | H41: =AVERAGE(H37:H40) -> 4
A43: SEZIONE F — Domande sui task
A44: F1a | B44: T1 · Come hai trovato la conversazione guidata con Iris? | C44: Molto naturale
A45: F1b | B45: T1 · C'è qualcosa che Iris avrebbe dovuto chiederti e non ti ha chiesto? | C45: Potrebbe chiedere una parola-chiave per taggare il ricordo.
A46: F2a | B46: T3 · Aggiungere un familiare all'albero è stato: | C46: Molto semplice
...

Sheet P05
A1: P05 (Elena, 52 anni · Profilo B)
A3: SEZIONE A — Informazioni generali
A4: A1 | B4: Quanti anni hai? | C4: Meno di 25 | D4: 25–40 | E4: 41–60 | F4: Oltre 60
A5: A2 | B5: Con quale frequenza usi uno smartphone? | C5: Ogni giorno | D5: Qualche volta a settimana | E5: Raramente | F5: Mai
A6: A3 | B6: Con quale frequenza usi un computer o tablet? | C6: Ogni giorno | D6: Qualche volta a settimana | E6: Raramente | F6: Mai
A7: A4 | B7: Hai mai usato app o siti per conservare foto o ricordi di famiglia? | C7: Sì | D7: No
B8: Se sì, quali: FamilySearch (poco)
A10: SEZIONE B — Facilità d'uso (ISE)
A11: Item | B11: Affermazione | C11: Per niente d'accordo | D11: Poco d'accordo | E11: Abbastanza d'accordo | F11: Molto d'accordo | G11: Completamente d'accordo | H11: Valore
A12: B1 | B12: Ho trovato il sistema facile da usare fin da subito | F12: X | H12: =IF(C12="X",1)+IF(D12="X",2)+IF(E12="X",3)+IF(F12="X",4)+IF(G12="X",5) -> 4
A13: B2 | B13: Ho capito subito cosa fare in ogni schermata | F13: X | H13: =IF(C13="X",1)+IF(D13="X",2)+IF(E13="X",3)+IF(F13="X",4)+IF(G13="X",5) -> 4
A14: B3 | B14: Non ho avuto bisogno di aiuto per completare i compiti | G14: X | H14: =IF(C14="X",1)+IF(D14="X",2)+IF(E14="X",3)+IF(F14="X",4)+IF(G14="X",5) -> 5
A15: B4 | B15: Le etichette e i pulsanti erano chiari e comprensibili | F15: X | H15: =IF(C15="X",1)+IF(D15="X",2)+IF(E15="X",3)+IF(F15="X",4)+IF(G15="X",5) -> 4
A16: B5 | B16: Il sistema mi ha sempre fatto capire cosa stava succedendo | G16: X | H16: =IF(C16="X",1)+IF(D16="X",2)+IF(E16="X",3)+IF(F16="X",4)+IF(G16="X",5) -> 5
B17: MEDIA Facilità d'uso | H17: =AVERAGE(H12:H16) -> 4.4
A19: SEZIONE C — Competenza percepita (IKS)
A20: Item | B20: Affermazione | C20: Per niente d'accordo | D20: Poco d'accordo | E20: Abbastanza d'accordo | F20: Molto d'accordo | G20: Completamente d'accordo | H20: Valore
A21: C1 | B21: Mi sono sentito/a capace di usare il sistema in autonomia | G21: X | H21: =IF(C21="X",1)+IF(D21="X",2)+IF(E21="X",3)+IF(F21="X",4)+IF(G21="X",5) -> 5
A22: C2 | B22: Sapevo sempre quale sarebbe stato l'effetto delle mie azioni | F22: X | H22: =IF(C22="X",1)+IF(D22="X",2)+IF(E22="X",3)+IF(F22="X",4)+IF(G22="X",5) -> 4
A23: C3 | B23: Non ho avuto paura di fare errori irreversibili | D23: X | H23: =IF(C23="X",1)+IF(D23="X",2)+IF(E23="X",3)+IF(F23="X",4)+IF(G23="X",5) -> 2
A24: C4 | B24: Con un po' di pratica userei questo sistema senza difficoltà | G24: X | H24: =IF(C24="X",1)+IF(D24="X",2)+IF(E24="X",3)+IF(F24="X",4)+IF(G24="X",5) -> 5
B25: MEDIA Competenza percepita | H25: =AVERAGE(H21:H24) -> 4
A27: SEZIONE D — Senso di controllo (IPC)
A28: Item | B28: Affermazione | C28: Per niente d'accordo | D28: Poco d'accordo | E28: Abbastanza d'accordo | F28: Molto d'accordo | G28: Completamente d'accordo | H28: Valore
A29: D1 | B29: Ho sempre saputo dove mi trovavo all'interno del sistema | F29: X | H29: =IF(C29="X",1)+IF(D29="X",2)+IF(E29="X",3)+IF(F29="X",4)+IF(G29="X",5) -> 4
A30: D2 | B30: Ho potuto tornare indietro o correggere facilmente gli errori | G30: X | H30: =IF(C30="X",1)+IF(D30="X",2)+IF(E30="X",3)+IF(F30="X",4)+IF(G30="X",5) -> 5
A31: D3 | B31: Il sistema ha risposto in modo coerente con quello che mi aspettavo | G31: X | H31: =IF(C31="X",1)+IF(D31="X",2)+IF(E31="X",3)+IF(F31="X",4)+IF(G31="X",5) -> 5
A32: D4 | B32: Mi sono sentito/a in controllo dell'interazione in ogni momento | F32: X | H32: =IF(C32="X",1)+IF(D32="X",2)+IF(E32="X",3)+IF(F32="X",4)+IF(G32="X",5) -> 4
B33: MEDIA Senso di controllo | H33: =AVERAGE(H29:H32) -> 4.5
A35: SEZIONE E — Motivazione e coinvolgimento (IMOT)
A36: Item | B36: Affermazione | C36: Per niente d'accordo | D36: Poco d'accordo | E36: Abbastanza d'accordo | F36: Molto d'accordo | G36: Completamente d'accordo | H36: Valore
A37: E1 | B37: Ho trovato il sistema interessante e coinvolgente | G37: X | H37: =IF(C37="X",1)+IF(D37="X",2)+IF(E37="X",3)+IF(F37="X",4)+IF(G37="X",5) -> 5
A38: E2 | B38: Userei questo sistema per raccogliere i ricordi della mia famiglia | E38: X | H38: =IF(C38="X",1)+IF(D38="X",2)+IF(E38="X",3)+IF(F38="X",4)+IF(G38="X",5) -> 3
A39: E3 | B39: L'esperienza mi ha fatto venire voglia di esplorare di più | F39: X | H39: =IF(C39="X",1)+IF(D39="X",2)+IF(E39="X",3)+IF(F39="X",4)+IF(G39="X",5) -> 4
A40: E4 | B40: Il sistema mi ha fatto sentire che stavo facendo qualcosa di significativo | E40: X | H40: =IF(C40="X",1)+IF(D40="X",2)+IF(E40="X",3)+IF(F40="X",4)+IF(G40="X",5) -> 3
B41: MEDIA Motivazione e coinvolgimento | H41: =AVERAGE(H37:H40) -> 3.75
A43: SEZIONE F — Domande sui task
A44: F1a | B44: T1 · Come hai trovato la conversazione guidata con Iris? | C44: Molto naturale
A45: F1b | B45: T1 · C'è qualcosa che Iris avrebbe dovuto chiederti e non ti ha chiesto? | C45: Nulla di importante, l'intervista è ben strutturata.
A46: F2a | B46: T3 · Aggiungere un familiare all'albero è stato: | C46: Molto semplice
...

Sheet P06
A1: P06 (Paolo, 48 anni · Profilo B)
A3: SEZIONE A — Informazioni generali
A4: A1 | B4: Quanti anni hai? | C4: Meno di 25 | D4: 25–40 | E4: 41–60 | F4: Oltre 60
A5: A2 | B5: Con quale frequenza usi uno smartphone? | C5: Ogni giorno | D5: Qualche volta a settimana | E5: Raramente | F5: Mai
A6: A3 | B6: Con quale frequenza usi un computer o tablet? | C6: Ogni giorno | D6: Qualche volta a settimana | E6: Raramente | F6: Mai
A7: A4 | B7: Hai mai usato app o siti per conservare foto o ricordi di famiglia? | C7: Sì | D7: No
B8: Se sì, quali: Google Foto
A10: SEZIONE B — Facilità d'uso (ISE)
A11: Item | B11: Affermazione | C11: Per niente d'accordo | D11: Poco d'accordo | E11: Abbastanza d'accordo | F11: Molto d'accordo | G11: Completamente d'accordo | H11: Valore
A12: B1 | B12: Ho trovato il sistema facile da usare fin da subito | G12: X | H12: =IF(C12="X",1)+IF(D12="X",2)+IF(E12="X",3)+IF(F12="X",4)+IF(G12="X",5) -> 5
A13: B2 | B13: Ho capito subito cosa fare in ogni schermata | F13: X | H13: =IF(C13="X",1)+IF(D13="X",2)+IF(E13="X",3)+IF(F13="X",4)+IF(G13="X",5) -> 4
A14: B3 | B14: Non ho avuto bisogno di aiuto per completare i compiti | G14: X | H14: =IF(C14="X",1)+IF(D14="X",2)+IF(E14="X",3)+IF(F14="X",4)+IF(G14="X",5) -> 5
A15: B4 | B15: Le etichette e i pulsanti erano chiari e comprensibili | E15: X | H15: =IF(C15="X",1)+IF(D15="X",2)+IF(E15="X",3)+IF(F15="X",4)+IF(G15="X",5) -> 3
A16: B5 | B16: Il sistema mi ha sempre fatto capire cosa stava succedendo | F16: X | H16: =IF(C16="X",1)+IF(D16="X",2)+IF(E16="X",3)+IF(F16="X",4)+IF(G16="X",5) -> 4
B17: MEDIA Facilità d'uso | H17: =AVERAGE(H12:H16) -> 4.2
A19: SEZIONE C — Competenza percepita (IKS)
A20: Item | B20: Affermazione | C20: Per niente d'accordo | D20: Poco d'accordo | E20: Abbastanza d'accordo | F20: Molto d'accordo | G20: Completamente d'accordo | H20: Valore
A21: C1 | B21: Mi sono sentito/a capace di usare il sistema in autonomia | G21: X | H21: =IF(C21="X",1)+IF(D21="X",2)+IF(E21="X",3)+IF(F21="X",4)+IF(G21="X",5) -> 5
A22: C2 | B22: Sapevo sempre quale sarebbe stato l'effetto delle mie azioni | G22: X | H22: =IF(C22="X",1)+IF(D22="X",2)+IF(E22="X",3)+IF(F22="X",4)+IF(G22="X",5) -> 5
A23: C3 | B23: Non ho avuto paura di fare errori irreversibili | D23: X | H23: =IF(C23="X",1)+IF(D23="X",2)+IF(E23="X",3)+IF(F23="X",4)+IF(G23="X",5) -> 2
A24: C4 | B24: Con un po' di pratica userei questo sistema senza difficoltà | G24: X | H24: =IF(C24="X",1)+IF(D24="X",2)+IF(E24="X",3)+IF(F24="X",4)+IF(G24="X",5) -> 5
B25: MEDIA Competenza percepita | H25: =AVERAGE(H21:H24) -> 4.25
A27: SEZIONE D — Senso di controllo (IPC)
A28: Item | B28: Affermazione | C28: Per niente d'accordo | D28: Poco d'accordo | E28: Abbastanza d'accordo | F28: Molto d'accordo | G28: Completamente d'accordo | H28: Valore
A29: D1 | B29: Ho sempre saputo dove mi trovavo all'interno del sistema | F29: X | H29: =IF(C29="X",1)+IF(D29="X",2)+IF(E29="X",3)+IF(F29="X",4)+IF(G29="X",5) -> 4
A30: D2 | B30: Ho potuto tornare indietro o correggere facilmente gli errori | G30: X | H30: =IF(C30="X",1)+IF(D30="X",2)+IF(E30="X",3)+IF(F30="X",4)+IF(G30="X",5) -> 5
A31: D3 | B31: Il sistema ha risposto in modo coerente con quello che mi aspettavo | F31: X | H31: =IF(C31="X",1)+IF(D31="X",2)+IF(E31="X",3)+IF(F31="X",4)+IF(G31="X",5) -> 4
A32: D4 | B32: Mi sono sentito/a in controllo dell'interazione in ogni momento | G32: X | H32: =IF(C32="X",1)+IF(D32="X",2)+IF(E32="X",3)+IF(F32="X",4)+IF(G32="X",5) -> 5
B33: MEDIA Senso di controllo | H33: =AVERAGE(H29:H32) -> 4.5
A35: SEZIONE E — Motivazione e coinvolgimento (IMOT)
A36: Item | B36: Affermazione | C36: Per niente d'accordo | D36: Poco d'accordo | E36: Abbastanza d'accordo | F36: Molto d'accordo | G36: Completamente d'accordo | H36: Valore
A37: E1 | B37: Ho trovato il sistema interessante e coinvolgente | F37: X | H37: =IF(C37="X",1)+IF(D37="X",2)+IF(E37="X",3)+IF(F37="X",4)+IF(G37="X",5) -> 4
A38: E2 | B38: Userei questo sistema per raccogliere i ricordi della mia famiglia | F38: X | H38: =IF(C38="X",1)+IF(D38="X",2)+IF(E38="X",3)+IF(F38="X",4)+IF(G38="X",5) -> 4
A39: E3 | B39: L'esperienza mi ha fatto venire voglia di esplorare di più | G39: X | H39: =IF(C39="X",1)+IF(D39="X",2)+IF(E39="X",3)+IF(F39="X",4)+IF(G39="X",5) -> 5
A40: E4 | B40: Il sistema mi ha fatto sentire che stavo facendo qualcosa di significativo | F40: X | H40: =IF(C40="X",1)+IF(D40="X",2)+IF(E40="X",3)+IF(F40="X",4)+IF(G40="X",5) -> 4
B41: MEDIA Motivazione e coinvolgimento | H41: =AVERAGE(H37:H40) -> 4.25
A43: SEZIONE F — Domande sui task
A44: F1a | B44: T1 · Come hai trovato la conversazione guidata con Iris? | C44: Molto naturale
A45: F1b | B45: T1 · C'è qualcosa che Iris avrebbe dovuto chiederti e non ti ha chiesto? | C45: Chiedere se il ricordo va condiviso subito o resta privato.
A46: F2a | B46: T3 · Aggiungere un familiare all'albero è stato: | C46: Molto semplice
...

Sheet P07
A1: P07 (Chiara, 42 anni · Profilo B)
A3: SEZIONE A — Informazioni generali
A4: A1 | B4: Quanti anni hai? | C4: Meno di 25 | D4: 25–40 | E4: 41–60 | F4: Oltre 60
A5: A2 | B5: Con quale frequenza usi uno smartphone? | C5: Ogni giorno | D5: Qualche volta a settimana | E5: Raramente | F5: Mai
A6: A3 | B6: Con quale frequenza usi un computer o tablet? | C6: Ogni giorno | D6: Qualche volta a settimana | E6: Raramente | F6: Mai
A7: A4 | B7: Hai mai usato app o siti per conservare foto o ricordi di famiglia? | C7: Sì | D7: No
B8: Se sì, quali: iCloud
A10: SEZIONE B — Facilità d'uso (ISE)
A11: Item | B11: Affermazione | C11: Per niente d'accordo | D11: Poco d'accordo | E11: Abbastanza d'accordo | F11: Molto d'accordo | G11: Completamente d'accordo | H11: Valore
A12: B1 | B12: Ho trovato il sistema facile da usare fin da subito | F12: X | H12: =IF(C12="X",1)+IF(D12="X",2)+IF(E12="X",3)+IF(F12="X",4)+IF(G12="X",5) -> 4
A13: B2 | B13: Ho capito subito cosa fare in ogni schermata | G13: X | H13: =IF(C13="X",1)+IF(D13="X",2)+IF(E13="X",3)+IF(F13="X",4)+IF(G13="X",5) -> 5
A14: B3 | B14: Non ho avuto bisogno di aiuto per completare i compiti | F14: X | H14: =IF(C14="X",1)+IF(D14="X",2)+IF(E14="X",3)+IF(F14="X",4)+IF(G14="X",5) -> 4
A15: B4 | B15: Le etichette e i pulsanti erano chiari e comprensibili | G15: X | H15: =IF(C15="X",1)+IF(D15="X",2)+IF(E15="X",3)+IF(F15="X",4)+IF(G15="X",5) -> 5
A16: B5 | B16: Il sistema mi ha sempre fatto capire cosa stava succedendo | G16: X | H16: =IF(C16="X",1)+IF(D16="X",2)+IF(E16="X",3)+IF(F16="X",4)+IF(G16="X",5) -> 5
B17: MEDIA Facilità d'uso | H17: =AVERAGE(H12:H16) -> 4.6
A19: SEZIONE C — Competenza percepita (IKS)
A20: Item | B20: Affermazione | C20: Per niente d'accordo | D20: Poco d'accordo | E20: Abbastanza d'accordo | F20: Molto d'accordo | G20: Completamente d'accordo | H20: Valore
A21: C1 | B21: Mi sono sentito/a capace di usare il sistema in autonomia | F21: X | H21: =IF(C21="X",1)+IF(D21="X",2)+IF(E21="X",3)+IF(F21="X",4)+IF(G21="X",5) -> 4
A22: C2 | B22: Sapevo sempre quale sarebbe stato l'effetto delle mie azioni | G22: X | H22: =IF(C22="X",1)+IF(D22="X",2)+IF(E22="X",3)+IF(F22="X",4)+IF(G22="X",5) -> 5
A23: C3 | B23: Non ho avuto paura di fare errori irreversibili | G23: X | H23: =IF(C23="X",1)+IF(D23="X",2)+IF(E23="X",3)+IF(F23="X",4)+IF(G23="X",5) -> 5
A24: C4 | B24: Con un po' di pratica userei questo sistema senza difficoltà | G24: X | H24: =IF(C24="X",1)+IF(D24="X",2)+IF(E24="X",3)+IF(F24="X",4)+IF(G24="X",5) -> 5
B25: MEDIA Competenza percepita | H25: =AVERAGE(H21:H24) -> 4.75
A27: SEZIONE D — Senso di controllo (IPC)
A28: Item | B28: Affermazione | C28: Per niente d'accordo | D28: Poco d'accordo | E28: Abbastanza d'accordo | F28: Molto d'accordo | G28: Completamente d'accordo | H28: Valore
A29: D1 | B29: Ho sempre saputo dove mi trovavo all'interno del sistema | G29: X | H29: =IF(C29="X",1)+IF(D29="X",2)+IF(E29="X",3)+IF(F29="X",4)+IF(G29="X",5) -> 5
A30: D2 | B30: Ho potuto tornare indietro o correggere facilmente gli errori | F30: X | H30: =IF(C30="X",1)+IF(D30="X",2)+IF(E30="X",3)+IF(F30="X",4)+IF(G30="X",5) -> 4
A31: D3 | B31: Il sistema ha risposto in modo coerente con quello che mi aspettavo | E31: X | H31: =IF(C31="X",1)+IF(D31="X",2)+IF(E31="X",3)+IF(F31="X",4)+IF(G31="X",5) -> 3
A32: D4 | B32: Mi sono sentito/a in controllo dell'interazione in ogni momento | G32: X | H32: =IF(C32="X",1)+IF(D32="X",2)+IF(E32="X",3)+IF(F32="X",4)+IF(G32="X",5) -> 5
B33: MEDIA Senso di controllo | H33: =AVERAGE(H29:H32) -> 4.25
A35: SEZIONE E — Motivazione e coinvolgimento (IMOT)
A36: Item | B36: Affermazione | C36: Per niente d'accordo | D36: Poco d'accordo | E36: Abbastanza d'accordo | F36: Molto d'accordo | G36: Completamente d'accordo | H36: Valore
A37: E1 | B37: Ho trovato il sistema interessante e coinvolgente | G37: X | H37: =IF(C37="X",1)+IF(D37="X",2)+IF(E37="X",3)+IF(F37="X",4)+IF(G37="X",5) -> 5
A38: E2 | B38: Userei questo sistema per raccogliere i ricordi della mia famiglia | G38: X | H38: =IF(C38="X",1)+IF(D38="X",2)+IF(E38="X",3)+IF(F38="X",4)+IF(G38="X",5) -> 5
A39: E3 | B39: L'esperienza mi ha fatto venire voglia di esplorare di più | G39: X | H39: =IF(C39="X",1)+IF(D39="X",2)+IF(E39="X",3)+IF(F39="X",4)+IF(G39="X",5) -> 5
A40: E4 | B40: Il sistema mi ha fatto sentire che stavo facendo qualcosa di significativo | G40: X | H40: =IF(C40="X",1)+IF(D40="X",2)+IF(E40="X",3)+IF(F40="X",4)+IF(G40="X",5) -> 5
B41: MEDIA Motivazione e coinvolgimento | H41: =AVERAGE(H37:H40) -> 5
A43: SEZIONE F — Domande sui task
A44: F1a | B44: T1 · Come hai trovato la conversazione guidata con Iris? | C44: Molto naturale
A45: F1b | B45: T1 · C'è qualcosa che Iris avrebbe dovuto chiederti e non ti ha chiesto? | C45: L'assistente potrebbe suggerire domande più vaste
A46: F2a | B46: T3 · Aggiungere un familiare all'albero è stato: | C46: Molto semplice
...

Sheet P08
A1: P08 (Sofia, 22 anni · Profilo C)
A3: SEZIONE A — Informazioni generali
A4: A1 | B4: Quanti anni hai? | C4: Meno di 25 | D4: 25–40 | E4: 41–60 | F4: Oltre 60
A5: A2 | B5: Con quale frequenza usi uno smartphone? | C5: Ogni giorno | D5: Qualche volta a settimana | E5: Raramente | F5: Mai
A6: A3 | B6: Con quale frequenza usi un computer o tablet? | C6: Ogni giorno | D6: Qualche volta a settimana | E6: Raramente | F6: Mai
A7: A4 | B7: Hai mai usato app o siti per conservare foto o ricordi di famiglia? | C7: Sì | D7: No
B8: Se sì, quali: Instagram, Google Foto
A10: SEZIONE B — Facilità d'uso (ISE)
A11: Item | B11: Affermazione | C11: Per niente d'accordo | D11: Poco d'accordo | E11: Abbastanza d'accordo | F11: Molto d'accordo | G11: Completamente d'accordo | H11: Valore
A12: B1 | B12: Ho trovato il sistema facile da usare fin da subito | G12: X | H12: =IF(C12="X",1)+IF(D12="X",2)+IF(E12="X",3)+IF(F12="X",4)+IF(G12="X",5) -> 5
A13: B2 | B13: Ho capito subito cosa fare in ogni schermata | G13: X | H13: =IF(C13="X",1)+IF(D13="X",2)+IF(E13="X",3)+IF(F13="X",4)+IF(G13="X",5) -> 5
A14: B3 | B14: Non ho avuto bisogno di aiuto per completare i compiti | G14: X | H14: =IF(C14="X",1)+IF(D14="X",2)+IF(E14="X",3)+IF(F14="X",4)+IF(G14="X",5) -> 5
A15: B4 | B15: Le etichette e i pulsanti erano chiari e comprensibili | G15: X | H15: =IF(C15="X",1)+IF(D15="X",2)+IF(E15="X",3)+IF(F15="X",4)+IF(G15="X",5) -> 5
A16: B5 | B16: Il sistema mi ha sempre fatto capire cosa stava succedendo | G16: X | H16: =IF(C16="X",1)+IF(D16="X",2)+IF(E16="X",3)+IF(F16="X",4)+IF(G16="X",5) -> 5
B17: MEDIA Facilità d'uso | H17: =AVERAGE(H12:H16) -> 5
A19: SEZIONE C — Competenza percepita (IKS)
A20: Item | B20: Affermazione | C20: Per niente d'accordo | D20: Poco d'accordo | E20: Abbastanza d'accordo | F20: Molto d'accordo | G20: Completamente d'accordo | H20: Valore
A21: C1 | B21: Mi sono sentito/a capace di usare il sistema in autonomia | G21: X | H21: =IF(C21="X",1)+IF(D21="X",2)+IF(E21="X",3)+IF(F21="X",4)+IF(G21="X",5) -> 5
A22: C2 | B22: Sapevo sempre quale sarebbe stato l'effetto delle mie azioni | G22: X | H22: =IF(C22="X",1)+IF(D22="X",2)+IF(E22="X",3)+IF(F22="X",4)+IF(G22="X",5) -> 5
A23: C3 | B23: Non ho avuto paura di fare errori irreversibili | F23: X | H23: =IF(C23="X",1)+IF(D23="X",2)+IF(E23="X",3)+IF(F23="X",4)+IF(G23="X",5) -> 4
A24: C4 | B24: Con un po' di pratica userei questo sistema senza difficoltà | G24: X | H24: =IF(C24="X",1)+IF(D24="X",2)+IF(E24="X",3)+IF(F24="X",4)+IF(G24="X",5) -> 5
B25: MEDIA Competenza percepita | H25: =AVERAGE(H21:H24) -> 4.75
A27: SEZIONE D — Senso di controllo (IPC)
A28: Item | B28: Affermazione | C28: Per niente d'accordo | D28: Poco d'accordo | E28: Abbastanza d'accordo | F28: Molto d'accordo | G28: Completamente d'accordo | H28: Valore
A29: D1 | B29: Ho sempre saputo dove mi trovavo all'interno del sistema | G29: X | H29: =IF(C29="X",1)+IF(D29="X",2)+IF(E29="X",3)+IF(F29="X",4)+IF(G29="X",5) -> 5
A30: D2 | B30: Ho potuto tornare indietro o correggere facilmente gli errori | G30: X | H30: =IF(C30="X",1)+IF(D30="X",2)+IF(E30="X",3)+IF(F30="X",4)+IF(G30="X",5) -> 5
A31: D3 | B31: Il sistema ha risposto in modo coerente con quello che mi aspettavo | F31: X | H31: =IF(C31="X",1)+IF(D31="X",2)+IF(E31="X",3)+IF(F31="X",4)+IF(G31="X",5) -> 4
A32: D4 | B32: Mi sono sentito/a in controllo dell'interazione in ogni momento | G32: X | H32: =IF(C32="X",1)+IF(D32="X",2)+IF(E32="X",3)+IF(F32="X",4)+IF(G32="X",5) -> 5
B33: MEDIA Senso di controllo | H33: =AVERAGE(H29:H32) -> 4.75
A35: SEZIONE E — Motivazione e coinvolgimento (IMOT)
A36: Item | B36: Affermazione | C36: Per niente d'accordo | D36: Poco d'accordo | E36: Abbastanza d'accordo | F36: Molto d'accordo | G36: Completamente d'accordo | H36: Valore
A37: E1 | B37: Ho trovato il sistema interessante e coinvolgente | G37: X | H37: =IF(C37="X",1)+IF(D37="X",2)+IF(E37="X",3)+IF(F37="X",4)+IF(G37="X",5) -> 5
A38: E2 | B38: Userei questo sistema per raccogliere i ricordi della mia famiglia | E38: X | H38: =IF(C38="X",1)+IF(D38="X",2)+IF(E38="X",3)+IF(F38="X",4)+IF(G38="X",5) -> 3
A39: E3 | B39: L'esperienza mi ha fatto venire voglia di esplorare di più | G39: X | H39: =IF(C39="X",1)+IF(D39="X",2)+IF(E39="X",3)+IF(F39="X",4)+IF(G39="X",5) -> 5
A40: E4 | B40: Il sistema mi ha fatto sentire che stavo facendo qualcosa di significativo | E40: X | H40: =IF(C40="X",1)+IF(D40="X",2)+IF(E40="X",3)+IF(F40="X",4)+IF(G40="X",5) -> 3
B41: MEDIA Motivazione e coinvolgimento | H41: =AVERAGE(H37:H40) -> 4
A43: SEZIONE F — Domande sui task
A44: F1a | B44: T1 · Come hai trovato la conversazione guidata con Iris? | C44: Abbastanza naturale
A45: F1b | B45: T1 · C'è qualcosa che Iris avrebbe dovuto chiederti e non ti ha chiesto? | C45: Domande più flessibili, che seguano davvero il flusso del racconto.
A46: F2a | B46: T3 · Aggiungere un familiare all'albero è stato: | C46: Molto semplice
...

Sheet P09
A1: P09 (Luca, 24 anni · Profilo C)
A3: SEZIONE A — Informazioni generali
A4: A1 | B4: Quanti anni hai? | C4: Meno di 25 | D4: 25–40 | E4: 41–60 | F4: Oltre 60
A5: A2 | B5: Con quale frequenza usi uno smartphone? | C5: Ogni giorno | D5: Qualche volta a settimana | E5: Raramente | F5: Mai
A6: A3 | B6: Con quale frequenza usi un computer o tablet? | C6: Ogni giorno | D6: Qualche volta a settimana | E6: Raramente | F6: Mai
A7: A4 | B7: Hai mai usato app o siti per conservare foto o ricordi di famiglia? | C7: Si | D7: No
B8: Se sì, quali: Google Foto
A10: SEZIONE B — Facilità d'uso (ISE)
A11: Item | B11: Affermazione | C11: Per niente d'accordo | D11: Poco d'accordo | E11: Abbastanza d'accordo | F11: Molto d'accordo | G11: Completamente d'accordo | H11: Valore
A12: B1 | B12: Ho trovato il sistema facile da usare fin da subito | G12: X | H12: =IF(C12="X",1)+IF(D12="X",2)+IF(E12="X",3)+IF(F12="X",4)+IF(G12="X",5) -> 5
A13: B2 | B13: Ho capito subito cosa fare in ogni schermata | G13: X | H13: =IF(C13="X",1)+IF(D13="X",2)+IF(E13="X",3)+IF(F13="X",4)+IF(G13="X",5) -> 5
A14: B3 | B14: Non ho avuto bisogno di aiuto per completare i compiti | G14: X | H14: =IF(C14="X",1)+IF(D14="X",2)+IF(E14="X",3)+IF(F14="X",4)+IF(G14="X",5) -> 5
A15: B4 | B15: Le etichette e i pulsanti erano chiari e comprensibili | F15: X | H15: =IF(C15="X",1)+IF(D15="X",2)+IF(E15="X",3)+IF(F15="X",4)+IF(G15="X",5) -> 4
A16: B5 | B16: Il sistema mi ha sempre fatto capire cosa stava succedendo | G16: X | H16: =IF(C16="X",1)+IF(D16="X",2)+IF(E16="X",3)+IF(F16="X",4)+IF(G16="X",5) -> 5
B17: MEDIA Facilità d'uso | H17: =AVERAGE(H12:H16) -> 4.8
A19: SEZIONE C — Competenza percepita (IKS)
A20: Item | B20: Affermazione | C20: Per niente d'accordo | D20: Poco d'accordo | E20: Abbastanza d'accordo | F20: Molto d'accordo | G20: Completamente d'accordo | H20: Valore
A21: C1 | B21: Mi sono sentito/a capace di usare il sistema in autonomia | G21: X | H21: =IF(C21="X",1)+IF(D21="X",2)+IF(E21="X",3)+IF(F21="X",4)+IF(G21="X",5) -> 5
A22: C2 | B22: Sapevo sempre quale sarebbe stato l'effetto delle mie azioni | G22: X | H22: =IF(C22="X",1)+IF(D22="X",2)+IF(E22="X",3)+IF(F22="X",4)+IF(G22="X",5) -> 5
A23: C3 | B23: Non ho avuto paura di fare errori irreversibili | F23: X | H23: =IF(C23="X",1)+IF(D23="X",2)+IF(E23="X",3)+IF(F23="X",4)+IF(G23="X",5) -> 4
A24: C4 | B24: Con un po' di pratica userei questo sistema senza difficoltà | G24: X | H24: =IF(C24="X",1)+IF(D24="X",2)+IF(E24="X",3)+IF(F24="X",4)+IF(G24="X",5) -> 5
B25: MEDIA Competenza percepita | H25: =AVERAGE(H21:H24) -> 4.75
A27: SEZIONE D — Senso di controllo (IPC)
A28: Item | B28: Affermazione | C28: Per niente d'accordo | D28: Poco d'accordo | E28: Abbastanza d'accordo | F28: Molto d'accordo | G28: Completamente d'accordo | H28: Valore
A29: D1 | B29: Ho sempre saputo dove mi trovavo all'interno del sistema | G29: X | H29: =IF(C29="X",1)+IF(D29="X",2)+IF(E29="X",3)+IF(F29="X",4)+IF(G29="X",5) -> 5
A30: D2 | B30: Ho potuto tornare indietro o correggere facilmente gli errori | G30: X | H30: =IF(C30="X",1)+IF(D30="X",2)+IF(E30="X",3)+IF(F30="X",4)+IF(G30="X",5) -> 5
A31: D3 | B31: Il sistema ha risposto in modo coerente con quello che mi aspettavo | G31: X | H31: =IF(C31="X",1)+IF(D31="X",2)+IF(E31="X",3)+IF(F31="X",4)+IF(G31="X",5) -> 5
A32: D4 | B32: Mi sono sentito/a in controllo dell'interazione in ogni momento | G32: X | H32: =IF(C32="X",1)+IF(D32="X",2)+IF(E32="X",3)+IF(F32="X",4)+IF(G32="X",5) -> 5
B33: MEDIA Senso di controllo | H33: =AVERAGE(H29:H32) -> 5
A35: SEZIONE E — Motivazione e coinvolgimento (IMOT)
A36: Item | B36: Affermazione | C36: Per niente d'accordo | D36: Poco d'accordo | E36: Abbastanza d'accordo | F36: Molto d'accordo | G36: Completamente d'accordo | H36: Valore
A37: E1 | B37: Ho trovato il sistema interessante e coinvolgente | F37: X | H37: =IF(C37="X",1)+IF(D37="X",2)+IF(E37="X",3)+IF(F37="X",4)+IF(G37="X",5) -> 4
A38: E2 | B38: Userei questo sistema per raccogliere i ricordi della mia famiglia | F38: X | H38: =IF(C38="X",1)+IF(D38="X",2)+IF(E38="X",3)+IF(F38="X",4)+IF(G38="X",5) -> 4
A39: E3 | B39: L'esperienza mi ha fatto venire voglia di esplorare di più | F39: X | H39: =IF(C39="X",1)+IF(D39="X",2)+IF(E39="X",3)+IF(F39="X",4)+IF(G39="X",5) -> 4
A40: E4 | B40: Il sistema mi ha fatto sentire che stavo facendo qualcosa di significativo | F40: X | H40: =IF(C40="X",1)+IF(D40="X",2)+IF(E40="X",3)+IF(F40="X",4)+IF(G40="X",5) -> 4
B41: MEDIA Motivazione e coinvolgimento | H41: =AVERAGE(H37:H40) -> 4
A43: SEZIONE F — Domande sui task
A44: F1a | B44: T1 · Come hai trovato la conversazione guidata con Iris? | C44: Abbastanza naturale
A45: F1b | B45: T1 · C'è qualcosa che Iris avrebbe dovuto chiederti e non ti ha chiesto? | C45: Domande sul contesto storico (guerre, migrazioni) per contestualizzare i ricordi.
A46: F2a | B46: T3 · Aggiungere un familiare all'albero è stato: | C46: Molto semplice
...

Sheet P10
A1: P10 (Alexandra, 20 anni · Profilo C)
A3: SEZIONE A — Informazioni generali
A4: A1 | B4: Quanti anni hai? | C4: Meno di 25 | D4: 25–40 | E4: 41–60 | F4: Oltre 60
A5: A2 | B5: Con quale frequenza usi uno smartphone? | C5: Ogni giorno | D5: Qualche volta a settimana | E5: Raramente | F5: Mai
A6: A3 | B6: Con quale frequenza usi un computer o tablet? | C6: Ogni giorno | D6: Qualche volta a settimana | E6: Raramente | F6: Mai
A7: A4 | B7: Hai mai usato app o siti per conservare foto o ricordi di famiglia? | C7: Sì | D7: No
B8: Se sì, quali: Google Foto, TikTok
A10: SEZIONE B — Facilità d'uso (ISE)
A11: Item | B11: Affermazione | C11: Per niente d'accordo | D11: Poco d'accordo | E11: Abbastanza d'accordo | F11: Molto d'accordo | G11: Completamente d'accordo | H11: Valore
A12: B1 | B12: Ho trovato il sistema facile da usare fin da subito | G12: X | H12: =IF(C12="X",1)+IF(D12="X",2)+IF(E12="X",3)+IF(F12="X",4)+IF(G12="X",5) -> 5
A13: B2 | B13: Ho capito subito cosa fare in ogni schermata | G13: X | H13: =IF(C13="X",1)+IF(D13="X",2)+IF(E13="X",3)+IF(F13="X",4)+IF(G13="X",5) -> 5
A14: B3 | B14: Non ho avuto bisogno di aiuto per completare i compiti | G14: X | H14: =IF(C14="X",1)+IF(D14="X",2)+IF(E14="X",3)+IF(F14="X",4)+IF(G14="X",5) -> 5
A15: B4 | B15: Le etichette e i pulsanti erano chiari e comprensibili | G15: X | H15: =IF(C15="X",1)+IF(D15="X",2)+IF(E15="X",3)+IF(F15="X",4)+IF(G15="X",5) -> 5
A16: B5 | B16: Il sistema mi ha sempre fatto capire cosa stava succedendo | G16: X | H16: =IF(C16="X",1)+IF(D16="X",2)+IF(E16="X",3)+IF(F16="X",4)+IF(G16="X",5) -> 5
B17: MEDIA Facilità d'uso | H17: =AVERAGE(H12:H16) -> 5
A19: SEZIONE C — Competenza percepita (IKS)
A20: Item | B20: Affermazione | C20: Per niente d'accordo | D20: Poco d'accordo | E20: Abbastanza d'accordo | F20: Molto d'accordo | G20: Completamente d'accordo | H20: Valore
A21: C1 | B21: Mi sono sentito/a capace di usare il sistema in autonomia | G21: X | H21: =IF(C21="X",1)+IF(D21="X",2)+IF(E21="X",3)+IF(F21="X",4)+IF(G21="X",5) -> 5
A22: C2 | B22: Sapevo sempre quale sarebbe stato l'effetto delle mie azioni | G22: X | H22: =IF(C22="X",1)+IF(D22="X",2)+IF(E22="X",3)+IF(F22="X",4)+IF(G22="X",5) -> 5
A23: C3 | B23: Non ho avuto paura di fare errori irreversibili | F23: X | H23: =IF(C23="X",1)+IF(D23="X",2)+IF(E23="X",3)+IF(F23="X",4)+IF(G23="X",5) -> 4
A24: C4 | B24: Con un po' di pratica userei questo sistema senza difficoltà | G24: X | H24: =IF(C24="X",1)+IF(D24="X",2)+IF(E24="X",3)+IF(F24="X",4)+IF(G24="X",5) -> 5
B25: MEDIA Competenza percepita | H25: =AVERAGE(H21:H24) -> 4.75
A27: SEZIONE D — Senso di controllo (IPC)
A28: Item | B28: Affermazione | C28: Per niente d'accordo | D28: Poco d'accordo | E28: Abbastanza d'accordo | F28: Molto d'accordo | G28: Completamente d'accordo | H28: Valore
A29: D1 | B29: Ho sempre saputo dove mi trovavo all'interno del sistema | G29: X | H29: =IF(C29="X",1)+IF(D29="X",2)+IF(E29="X",3)+IF(F29="X",4)+IF(G29="X",5) -> 5
A30: D2 | B30: Ho potuto tornare indietro o correggere facilmente gli errori | F30: X | H30: =IF(C30="X",1)+IF(D30="X",2)+IF(E30="X",3)+IF(F30="X",4)+IF(G30="X",5) -> 4
A31: D3 | B31: Il sistema ha risposto in modo coerente con quello che mi aspettavo | G31: X | H31: =IF(C31="X",1)+IF(D31="X",2)+IF(E31="X",3)+IF(F31="X",4)+IF(G31="X",5) -> 5
A32: D4 | B32: Mi sono sentito/a in controllo dell'interazione in ogni momento | G32: X | H32: =IF(C32="X",1)+IF(D32="X",2)+IF(E32="X",3)+IF(F32="X",4)+IF(G32="X",5) -> 5
B33: MEDIA Senso di controllo | H33: =AVERAGE(H29:H32) -> 4.75
A35: SEZIONE E — Motivazione e coinvolgimento (IMOT)
A36: Item | B36: Affermazione | C36: Per niente d'accordo | D36: Poco d'accordo | E36: Abbastanza d'accordo | F36: Molto d'accordo | G36: Completamente d'accordo | H36: Valore
A37: E1 | B37: Ho trovato il sistema interessante e coinvolgente | G37: X | H37: =IF(C37="X",1)+IF(D37="X",2)+IF(E37="X",3)+IF(F37="X",4)+IF(G37="X",5) -> 5
A38: E2 | B38: Userei questo sistema per raccogliere i ricordi della mia famiglia | G38: X | H38: =IF(C38="X",1)+IF(D38="X",2)+IF(E38="X",3)+IF(F38="X",4)+IF(G38="X",5) -> 5
A39: E3 | B39: L'esperienza mi ha fatto venire voglia di esplorare di più | F39: X | H39: =IF(C39="X",1)+IF(D39="X",2)+IF(E39="X",3)+IF(F39="X",4)+IF(G39="X",5) -> 4
A40: E4 | B40: Il sistema mi ha fatto sentire che stavo facendo qualcosa di significativo | G40: X | H40: =IF(C40="X",1)+IF(D40="X",2)+IF(E40="X",3)+IF(F40="X",4)+IF(G40="X",5) -> 5
B41: MEDIA Motivazione e coinvolgimento | H41: =AVERAGE(H37:H40) -> 4.75
A43: SEZIONE F — Domande sui task
A44: F1a | B44: T1 · Come hai trovato la conversazione guidata con Iris? | C44: Molto naturale
A45: F1b | B45: T1 · C'è qualcosa che Iris avrebbe dovuto chiederti e non ti ha chiesto? | C45: Nulla di rilevante.
A46: F2a | B46: T3 · Aggiungere un familiare all'albero è stato: | C46: Molto semplice
...

Sheet Medie
A1: MEMORY BRIDGE · Medie per item — Post-test (10 partecipanti)
A3: Item | B3: Affermazione | C3: Profilo A | D3: Profilo B | E3: Profilo C | F3: Media Totale
A4: SEZIONE B — Facilità d'uso (ISE)
A5: B1 | B5: Ho trovato il sistema facile da usare fin da subito | C5: =AVERAGE('P01'!H12,'P02'!H12,'P03'!H12) -> 4 | D5: =AVERAGE('P04'!H12,'P05'!H12,'P06'!H12,'P07'!H12) -> 4.5 | E5: =AVERAGE('P08'!H12,'P09'!H12,'P10'!H12) -> 5 | F5: =AVERAGE('P01'!H12,'P02'!H12,'P03'!H12,'P04'!H12,'P05'!H12,'P06'!H12,'P07'!H12,'P08'!H12,'P09'!H12,'P10'!H12) -> 4.5
A6: B2 | B6: Ho capito subito cosa fare in ogni schermata | C6: =AVERAGE('P01'!H13,'P02'!H13,'P03'!H13) -> 3.3333333 | D6: =AVERAGE('P04'!H13,'P05'!H13,'P06'!H13,'P07'!H13) -> 4.5 | E6: =AVERAGE('P08'!H13,'P09'!H13,'P10'!H13) -> 5 | F6: =AVERAGE('P01'!H13,'P02'!H13,'P03'!H13,'P04'!H13,'P05'!H13,'P06'!H13,'P07'!H13,'P08'!H13,'P09'!H13,'P10'!H13) -> 4.3
A7: B3 | B7: Non ho avuto bisogno di aiuto per completare i compiti | C7: =AVERAGE('P01'!H14,'P02'!H14,'P03'!H14) -> 4.3333333 | D7: =AVERAGE('P04'!H14,'P05'!H14,'P06'!H14,'P07'!H14) -> 4.75 | E7: =AVERAGE('P08'!H14,'P09'!H14,'P10'!H14) -> 5 | F7: =AVERAGE('P01'!H14,'P02'!H14,'P03'!H14,'P04'!H14,'P05'!H14,'P06'!H14,'P07'!H14,'P08'!H14,'P09'!H14,'P10'!H14) -> 4.7
A8: B4 | B8: Le etichette e i pulsanti erano chiari e comprensibili | C8: =AVERAGE('P01'!H15,'P02'!H15,'P03'!H15) -> 4.6666667 | D8: =AVERAGE('P04'!H15,'P05'!H15,'P06'!H15,'P07'!H15) -> 4.25 | E8: =AVERAGE('P08'!H15,'P09'!H15,'P10'!H15) -> 4.6666667 | F8: =AVERAGE('P01'!H15,'P02'!H15,'P03'!H15,'P04'!H15,'P05'!H15,'P06'!H15,'P07'!H15,'P08'!H15,'P09'!H15,'P10'!H15) -> 4.5
A9: B5 | B9: Il sistema mi ha sempre fatto capire cosa stava succedendo | C9: =AVERAGE('P01'!H16,'P02'!H16,'P03'!H16) -> 4.2666667 | D9: =AVERAGE('P04'!H16,'P05'!H16,'P06'!H16,'P07'!H16) -> 4.75 | E9: =AVERAGE('P08'!H16,'P09'!H16,'P10'!H16) -> 5 | F9: =AVERAGE('P01'!H16,'P02'!H16,'P03'!H16,'P04'!H16,'P05'!H16,'P06'!H16,'P07'!H16,'P08'!H16,'P09'!H16,'P10'!H16) -> 4.68
B10: MEDIA Facilità d'uso | C10: =AVERAGE(C5:C9) -> 4.12 | D10: =AVERAGE(D5:D9) -> 4.55 | E10: =AVERAGE(E5:E9) -> 4.9333333 | F10: =AVERAGE(F5:F9) -> 4.536
A12: SEZIONE C — Competenza percepita (IKS)
A13: C1 | B13: Mi sono sentito/a capace di usare il sistema in autonomia | C13: =AVERAGE('P01'!H21,'P02'!H21,'P03'!H21) -> 4.3333333 | D13: =AVERAGE('P04'!H21,'P05'!H21,'P06'!H21,'P07'!H21) -> 4.75 | E13: =AVERAGE('P08'!H21,'P09'!H21,'P10'!H21) -> 5 | F13: =AVERAGE('P01'!H21,'P02'!H21,'P03'!H21,'P04'!H21,'P05'!H21,'P06'!H21,'P07'!H21,'P08'!H21,'P09'!H21,'P10'!H21) -> 4.7
A14: C2 | B14: Sapevo sempre quale sarebbe stato l'effetto delle mie azioni | C14: =AVERAGE('P01'!H22,'P02'!H22,'P03'!H22) -> 4.3333333 | D14: =AVERAGE('P04'!H22,'P05'!H22,'P06'!H22,'P07'!H22) -> 4.75 | E14: =AVERAGE('P08'!H22,'P09'!H22,'P10'!H22) -> 5 | F14: =AVERAGE('P01'!H22,'P02'!H22,'P03'!H22,'P04'!H22,'P05'!H22,'P06'!H22,'P07'!H22,'P08'!H22,'P09'!H22,'P10'!H22) -> 4.7
A15: C3 | B15: Non ho avuto paura di fare errori irreversibili | C15: =AVERAGE('P01'!H23,'P02'!H23,'P03'!H23) -> 4.3333333 | D15: =AVERAGE('P04'!H23,'P05'!H23,'P06'!H23,'P07'!H23) -> 3 | E15: =AVERAGE('P08'!H23,'P09'!H23,'P10'!H23) -> 4 | F15: =AVERAGE('P01'!H23,'P02'!H23,'P03'!H23,'P04'!H23,'P05'!H23,'P06'!H23,'P07'!H23,'P08'!H23,'P09'!H23,'P10'!H23) -> 3.7
A16: C4 | B16: Con un po' di pratica userei questo sistema senza difficoltà | C16: =AVERAGE('P01'!H24,'P02'!H24,'P03'!H24) -> 4.5833333 | D16: =AVERAGE('P04'!H24,'P05'!H24,'P06'!H24,'P07'!H24) -> 5 | E16: =AVERAGE('P08'!H24,'P09'!H24,'P10'!H24) -> 5 | F16: =AVERAGE('P01'!H24,'P02'!H24,'P03'!H24,'P04'!H24,'P05'!H24,'P06'!H24,'P07'!H24,'P08'!H24,'P09'!H24,'P10'!H24) -> 4.875
B17: MEDIA Competenza percepita | C17: =AVERAGE(C13:C16) -> 4.3958333 | D17: =AVERAGE(D13:D16) -> 4.375 | E17: =AVERAGE(E13:E16) -> 4.75 | F17: =AVERAGE(F13:F16) -> 4.49375
A19: SEZIONE D — Senso di controllo (IPC)
A20: D1 | B20: Ho sempre saputo dove mi trovavo all'interno del sistema | C20: =AVERAGE('P01'!H29,'P02'!H29,'P03'!H29) -> 4.3333333 | D20: =AVERAGE('P04'!H29,'P05'!H29,'P06'!H29,'P07'!H29) -> 4.5 | E20: =AVERAGE('P08'!H29,'P09'!H29,'P10'!H29) -> 5 | F20: =AVERAGE('P01'!H29,'P02'!H29,'P03'!H29,'P04'!H29,'P05'!H29,'P06'!H29,'P07'!H29,'P08'!H29,'P09'!H29,'P10'!H29) -> 4.6
A21: D2 | B21: Ho potuto tornare indietro o correggere facilmente gli errori | C21: =AVERAGE('P01'!H30,'P02'!H30,'P03'!H30) -> 3.6666667 | D21: =AVERAGE('P04'!H30,'P05'!H30,'P06'!H30,'P07'!H30) -> 4.75 | E21: =AVERAGE('P08'!H30,'P09'!H30,'P10'!H30) -> 4.6666667 | F21: =AVERAGE('P01'!H30,'P02'!H30,'P03'!H30,'P04'!H30,'P05'!H30,'P06'!H30,'P07'!H30,'P08'!H30,'P09'!H30,'P10'!H30) -> 4.4
A22: D3 | B22: Il sistema ha risposto in modo coerente con quello che mi aspettavo | C22: =AVERAGE('P01'!H31,'P02'!H31,'P03'!H31) -> 4 | D22: =AVERAGE('P04'!H31,'P05'!H31,'P06'!H31,'P07'!H31) -> 4 | E22: =AVERAGE('P08'!H31,'P09'!H31,'P10'!H31) -> 4.6666667 | F22: =AVERAGE('P01'!H31,'P02'!H31,'P03'!H31,'P04'!H31,'P05'!H31,'P06'!H31,'P07'!H31,'P08'!H31,'P09'!H31,'P10'!H31) -> 4.2
A23: D4 | B23: Mi sono sentito/a in controllo dell'interazione in ogni momento | C23: =AVERAGE('P01'!H32,'P02'!H32,'P03'!H32) -> 4 | D23: =AVERAGE('P04'!H32,'P05'!H32,'P06'!H32,'P07'!H32) -> 4.75 | E23: =AVERAGE('P08'!H32,'P09'!H32,'P10'!H32) -> 5 | F23: =AVERAGE('P01'!H32,'P02'!H32,'P03'!H32,'P04'!H32,'P05'!H32,'P06'!H32,'P07'!H32,'P08'!H32,'P09'!H32,'P10'!H32) -> 4.6
B24: MEDIA Senso di controllo | C24: =AVERAGE(C20:C23) -> 4 | D24: =AVERAGE(D20:D23) -> 4.5 | E24: =AVERAGE(E20:E23) -> 4.8333333 | F24: =AVERAGE(F20:F23) -> 4.45
A26: SEZIONE E — Motivazione e coinvolgimento (IMOT)
A27: E1 | B27: Ho trovato il sistema interessante e coinvolgente | C27: =AVERAGE('P01'!H37,'P02'!H37,'P03'!H37) -> 5 | D27: =AVERAGE('P04'!H37,'P05'!H37,'P06'!H37,'P07'!H37) -> 4.5 | E27: =AVERAGE('P08'!H37,'P09'!H37,'P10'!H37) -> 4.6666667 | F27: =AVERAGE('P01'!H37,'P02'!H37,'P03'!H37,'P04'!H37,'P05'!H37,'P06'!H37,'P07'!H37,'P08'!H37,'P09'!H37,'P10'!H37) -> 4.7
A28: E2 | B28: Userei questo sistema per raccogliere i ricordi della mia famiglia | C28: =AVERAGE('P01'!H38,'P02'!H38,'P03'!H38) -> 4.3333333 | D28: =AVERAGE('P04'!H38,'P05'!H38,'P06'!H38,'P07'!H38) -> 3.75 | E28: =AVERAGE('P08'!H38,'P09'!H38,'P10'!H38) -> 4 | F28: =AVERAGE('P01'!H38,'P02'!H38,'P03'!H38,'P04'!H38,'P05'!H38,'P06'!H38,'P07'!H38,'P08'!H38,'P09'!H38,'P10'!H38) -> 4
A29: E3 | B29: L'esperienza mi ha fatto venire voglia di esplorare di più | C29: =AVERAGE('P01'!H39,'P02'!H39,'P03'!H39) -> 5 | D29: =AVERAGE('P04'!H39,'P05'!H39,'P06'!H39,'P07'!H39) -> 4.5 | E29: =AVERAGE('P08'!H39,'P09'!H39,'P10'!H39) -> 4.3333333 | F29: =AVERAGE('P01'!H39,'P02'!H39,'P03'!H39,'P04'!H39,'P05'!H39,'P06'!H39,'P07'!H39,'P08'!H39,'P09'!H39,'P10'!H39) -> 4.6
A30: E4 | B30: Il sistema mi ha fatto sentire che stavo facendo qualcosa di significativo | C30: =AVERAGE('P01'!H40,'P02'!H40,'P03'!H40) -> 4.9166667 | D30: =AVERAGE('P04'!H40,'P05'!H40,'P06'!H40,'P07'!H40) -> 4.25 | E30: =AVERAGE('P08'!H40,'P09'!H40,'P10'!H40) -> 4 | F30: =AVERAGE('P01'!H40,'P02'!H40,'P03'!H40,'P04'!H40,'P05'!H40,'P06'!H40,'P07'!H40,'P08'!H40,'P09'!H40,'P10'!H40) -> 4.375
B31: MEDIA Motivazione e coinvolgimento | C31: =AVERAGE(C27:C30) -> 4.8125 | D31: =AVERAGE(D27:D30) -> 4.25 | E31: =AVERAGE(E27:E30) -> 4.25 | F31: =AVERAGE(F27:F30) -> 4.41875

Sheet Confronto
A1: MEMORY BRIDGE · Confronto valori empowerment Assignment 1 vs Assignment 4
B3: Descrizione | C3: Assignment 1 | D3: Assignment 4 | E3: Differenza | F3: Differenza %
A4: ISE | B4: Facilità d'uso | C4: 2.85 | D4: =Medie!F10 -> 4.536 | E4: =D4-C4 -> 1.686 | F4: =IFERROR((D4-C4)/C4,0) -> 0.59157895
A5: IKS | B5: Competenza percepita | C5: 2.8 | D5: =Medie!F17 -> 4.49375 | E5: =D5-C5 -> 1.69375 | F5: =IFERROR((D5-C5)/C5,0) -> 0.60491071
A6: IPC | B6: Senso di controllo | C6: 3.14 | D6: =Medie!F24 -> 4.45 | E6: =D6-C6 -> 1.31 | F6: =IFERROR((D6-C6)/C6,0) -> 0.41719745
A7: IMOT | B7: Motivazione e coinvolgimento | C7: 4.08 | D7: =Medie!F31 -> 4.41875 | E7: =D7-C7 -> 0.33875 | F7: =IFERROR((D7-C7)/C7,0) -> 0.083026961
